/home/mrule/Dropbox/python_libraries/neurotools/source/neurotools.20150906_scatter_plots_demonstrating_that_PGD_threshold_creates_confound.rst:4: WARNING: autodoc: failed to import module u'neurotools.20150906_scatter_plots_demonstrating_that_PGD_threshold_creates_confound'; the following exception was raised:
Traceback (most recent call last):
  File "/usr/local/lib/python2.7/dist-packages/sphinx/ext/autodoc.py", line 551, in import_object
    __import__(self.modname)
ImportError: No module named 20150906_scatter_plots_demonstrating_that_PGD_threshold_creates_confound
/home/mrule/Dropbox/python_libraries/neurotools/source/neurotools.20150906_scatter_plots_demonstrating_that_PGD_threshold_creates_confound_2.rst:4: WARNING: autodoc: failed to import module u'neurotools.20150906_scatter_plots_demonstrating_that_PGD_threshold_creates_confound_2'; the following exception was raised:
Traceback (most recent call last):
  File "/usr/local/lib/python2.7/dist-packages/sphinx/ext/autodoc.py", line 551, in import_object
    __import__(self.modname)
ImportError: No module named 20150906_scatter_plots_demonstrating_that_PGD_threshold_creates_confound_2
/home/mrule/Dropbox/python_libraries/neurotools/source/neurotools.GLMFit.rst:4: WARNING: autodoc: failed to import module u'neurotools.GLMFit'; the following exception was raised:
Traceback (most recent call last):
  File "/usr/local/lib/python2.7/dist-packages/sphinx/ext/autodoc.py", line 551, in import_object
    __import__(self.modname)
ImportError: No module named GLMFit
/home/mrule/Dropbox/python_libraries/neurotools/source/neurotools.Statistics.rst:4: WARNING: autodoc: failed to import module u'neurotools.Statistics'; the following exception was raised:
Traceback (most recent call last):
  File "/usr/local/lib/python2.7/dist-packages/sphinx/ext/autodoc.py", line 551, in import_object
    __import__(self.modname)
ImportError: No module named Statistics
/home/mrule/Dropbox/python_libraries/neurotools/source/neurotools.amplitudetransients.rst:4: WARNING: autodoc: failed to import module u'neurotools.amplitudetransients'; the following exception was raised:
Traceback (most recent call last):
  File "/usr/local/lib/python2.7/dist-packages/sphinx/ext/autodoc.py", line 551, in import_object
    __import__(self.modname)
ImportError: No module named amplitudetransients
/home/mrule/Dropbox/python_libraries/neurotools/source/neurotools.array.rst:4: WARNING: autodoc: failed to import module u'neurotools.array'; the following exception was raised:
Traceback (most recent call last):
  File "/usr/local/lib/python2.7/dist-packages/sphinx/ext/autodoc.py", line 551, in import_object
    __import__(self.modname)
ImportError: No module named array
/home/mrule/Dropbox/python_libraries/neurotools/source/neurotools.arraytools.rst:4: WARNING: autodoc: failed to import module u'neurotools.arraytools'; the following exception was raised:
Traceback (most recent call last):
  File "/usr/local/lib/python2.7/dist-packages/sphinx/ext/autodoc.py", line 551, in import_object
    __import__(self.modname)
ImportError: No module named arraytools
/home/mrule/Dropbox/python_libraries/neurotools/source/neurotools.blackrock.rst:14: WARNING: autodoc: failed to import module u'neurotools.blackrock'; the following exception was raised:
Traceback (most recent call last):
  File "/usr/local/lib/python2.7/dist-packages/sphinx/ext/autodoc.py", line 551, in import_object
    __import__(self.modname)
ImportError: No module named blackrock
/home/mrule/Dropbox/python_libraries/neurotools/source/neurotools.blackrock.array.rst:4: WARNING: autodoc: failed to import module u'neurotools.blackrock.array'; the following exception was raised:
Traceback (most recent call last):
  File "/usr/local/lib/python2.7/dist-packages/sphinx/ext/autodoc.py", line 551, in import_object
    __import__(self.modname)
ImportError: No module named blackrock.array
/home/mrule/Dropbox/python_libraries/neurotools/source/neurotools.cache.rst:4: WARNING: autodoc: failed to import module u'neurotools.cache'; the following exception was raised:
Traceback (most recent call last):
  File "/usr/local/lib/python2.7/dist-packages/sphinx/ext/autodoc.py", line 551, in import_object
    __import__(self.modname)
ImportError: No module named cache
/home/mrule/Dropbox/python_libraries/neurotools/source/neurotools.clear.rst:4: WARNING: autodoc: failed to import module u'neurotools.clear'; the following exception was raised:
Traceback (most recent call last):
  File "/usr/local/lib/python2.7/dist-packages/sphinx/ext/autodoc.py", line 551, in import_object
    __import__(self.modname)
ImportError: No module named clear
/home/mrule/Dropbox/python_libraries/neurotools/source/neurotools.coherence.rst:4: WARNING: autodoc: failed to import module u'neurotools.coherence'; the following exception was raised:
Traceback (most recent call last):
  File "/usr/local/lib/python2.7/dist-packages/sphinx/ext/autodoc.py", line 551, in import_object
    __import__(self.modname)
ImportError: No module named coherence
/home/mrule/Dropbox/python_libraries/neurotools/source/neurotools.conv.rst:4: WARNING: autodoc: failed to import module u'neurotools.conv'; the following exception was raised:
Traceback (most recent call last):
  File "/usr/local/lib/python2.7/dist-packages/sphinx/ext/autodoc.py", line 551, in import_object
    __import__(self.modname)
ImportError: No module named conv
/home/mrule/Dropbox/python_libraries/neurotools/source/neurotools.convolutionalmodels.rst:4: WARNING: autodoc: failed to import module u'neurotools.convolutionalmodels'; the following exception was raised:
Traceback (most recent call last):
  File "/usr/local/lib/python2.7/dist-packages/sphinx/ext/autodoc.py", line 551, in import_object
    __import__(self.modname)
ImportError: No module named convolutionalmodels
/home/mrule/Dropbox/python_libraries/neurotools/source/neurotools.convtools.rst:4: WARNING: autodoc: failed to import module u'neurotools.convtools'; the following exception was raised:
Traceback (most recent call last):
  File "/usr/local/lib/python2.7/dist-packages/sphinx/ext/autodoc.py", line 551, in import_object
    __import__(self.modname)
ImportError: No module named convtools
/home/mrule/Dropbox/python_libraries/neurotools/source/neurotools.dct.rst:4: WARNING: autodoc: failed to import module u'neurotools.dct'; the following exception was raised:
Traceback (most recent call last):
  File "/usr/local/lib/python2.7/dist-packages/sphinx/ext/autodoc.py", line 551, in import_object
    __import__(self.modname)
ImportError: No module named dct
/home/mrule/Dropbox/python_libraries/neurotools/source/neurotools.decorator.rst:4: WARNING: autodoc: failed to import module u'neurotools.decorator'; the following exception was raised:
Traceback (most recent call last):
  File "/usr/local/lib/python2.7/dist-packages/sphinx/ext/autodoc.py", line 551, in import_object
    __import__(self.modname)
ImportError: No module named decorator
/home/mrule/Dropbox/python_libraries/neurotools/source/neurotools.density.rst:4: WARNING: autodoc: failed to import module u'neurotools.density'; the following exception was raised:
Traceback (most recent call last):
  File "/usr/local/lib/python2.7/dist-packages/sphinx/ext/autodoc.py", line 551, in import_object
    __import__(self.modname)
ImportError: No module named density
/home/mrule/Dropbox/python_libraries/neurotools/source/neurotools.densitytools.rst:4: WARNING: autodoc: failed to import module u'neurotools.densitytools'; the following exception was raised:
Traceback (most recent call last):
  File "/usr/local/lib/python2.7/dist-packages/sphinx/ext/autodoc.py", line 551, in import_object
    __import__(self.modname)
ImportError: No module named densitytools
/home/mrule/Dropbox/python_libraries/neurotools/source/neurotools.dependencies.rst:4: WARNING: autodoc: failed to import module u'neurotools.dependencies'; the following exception was raised:
Traceback (most recent call last):
  File "/usr/local/lib/python2.7/dist-packages/sphinx/ext/autodoc.py", line 551, in import_object
    __import__(self.modname)
ImportError: No module named dependencies
/home/mrule/Dropbox/python_libraries/neurotools/source/neurotools.distance.rst:4: WARNING: autodoc: failed to import module u'neurotools.distance'; the following exception was raised:
Traceback (most recent call last):
  File "/usr/local/lib/python2.7/dist-packages/sphinx/ext/autodoc.py", line 551, in import_object
    __import__(self.modname)
ImportError: No module named distance
/home/mrule/Dropbox/python_libraries/neurotools/source/neurotools.distancetools.rst:4: WARNING: autodoc: failed to import module u'neurotools.distancetools'; the following exception was raised:
Traceback (most recent call last):
  File "/usr/local/lib/python2.7/dist-packages/sphinx/ext/autodoc.py", line 551, in import_object
    __import__(self.modname)
ImportError: No module named distancetools
/home/mrule/Dropbox/python_libraries/neurotools/source/neurotools.entropy.rst:4: WARNING: autodoc: failed to import module u'neurotools.entropy'; the following exception was raised:
Traceback (most recent call last):
  File "/usr/local/lib/python2.7/dist-packages/sphinx/ext/autodoc.py", line 551, in import_object
    __import__(self.modname)
ImportError: No module named entropy
/home/mrule/Dropbox/python_libraries/neurotools/source/neurotools.fftzeros.rst:4: WARNING: autodoc: failed to import module u'neurotools.fftzeros'; the following exception was raised:
Traceback (most recent call last):
  File "/usr/local/lib/python2.7/dist-packages/sphinx/ext/autodoc.py", line 551, in import_object
    __import__(self.modname)
ImportError: No module named fftzeros
/home/mrule/Dropbox/python_libraries/neurotools/source/neurotools.glm.rst:4: WARNING: autodoc: failed to import module u'neurotools.glm'; the following exception was raised:
Traceback (most recent call last):
  File "/usr/local/lib/python2.7/dist-packages/sphinx/ext/autodoc.py", line 551, in import_object
    __import__(self.modname)
ImportError: No module named glm
/home/mrule/Dropbox/python_libraries/neurotools/source/neurotools.gpu.rst:16: WARNING: autodoc: failed to import module u'neurotools.gpu'; the following exception was raised:
Traceback (most recent call last):
  File "/usr/local/lib/python2.7/dist-packages/sphinx/ext/autodoc.py", line 551, in import_object
    __import__(self.modname)
ImportError: No module named gpu
/home/mrule/Dropbox/python_libraries/neurotools/source/neurotools.gpu.cl.rst:16: WARNING: autodoc: failed to import module u'neurotools.gpu.cl'; the following exception was raised:
Traceback (most recent call last):
  File "/usr/local/lib/python2.7/dist-packages/sphinx/ext/autodoc.py", line 551, in import_object
    __import__(self.modname)
ImportError: No module named gpu.cl
/home/mrule/Dropbox/python_libraries/neurotools/source/neurotools.gpu.cl.device.rst:4: WARNING: autodoc: failed to import module u'neurotools.gpu.cl.device'; the following exception was raised:
Traceback (most recent call last):
  File "/usr/local/lib/python2.7/dist-packages/sphinx/ext/autodoc.py", line 551, in import_object
    __import__(self.modname)
ImportError: No module named gpu.cl.device
/home/mrule/Dropbox/python_libraries/neurotools/source/neurotools.gpu.cl.function.rst:4: WARNING: autodoc: failed to import module u'neurotools.gpu.cl.function'; the following exception was raised:
Traceback (most recent call last):
  File "/usr/local/lib/python2.7/dist-packages/sphinx/ext/autodoc.py", line 551, in import_object
    __import__(self.modname)
ImportError: No module named gpu.cl.function
/home/mrule/Dropbox/python_libraries/neurotools/source/neurotools.gpu.cl.matrix.rst:4: WARNING: autodoc: failed to import module u'neurotools.gpu.cl.matrix'; the following exception was raised:
Traceback (most recent call last):
  File "/usr/local/lib/python2.7/dist-packages/sphinx/ext/autodoc.py", line 551, in import_object
    __import__(self.modname)
ImportError: No module named gpu.cl.matrix
/home/mrule/Dropbox/python_libraries/neurotools/source/neurotools.gpu.cpu.rst:14: WARNING: autodoc: failed to import module u'neurotools.gpu.cpu'; the following exception was raised:
Traceback (most recent call last):
  File "/usr/local/lib/python2.7/dist-packages/sphinx/ext/autodoc.py", line 551, in import_object
    __import__(self.modname)
ImportError: No module named gpu.cpu
/home/mrule/Dropbox/python_libraries/neurotools/source/neurotools.gpu.cpu.util.rst:4: WARNING: autodoc: failed to import module u'neurotools.gpu.cpu.util'; the following exception was raised:
Traceback (most recent call last):
  File "/usr/local/lib/python2.7/dist-packages/sphinx/ext/autodoc.py", line 551, in import_object
    __import__(self.modname)
ImportError: No module named gpu.cpu.util
/home/mrule/Dropbox/python_libraries/neurotools/source/neurotools.gpu.cu.rst:23: WARNING: autodoc: failed to import module u'neurotools.gpu.cu'; the following exception was raised:
Traceback (most recent call last):
  File "/usr/local/lib/python2.7/dist-packages/sphinx/ext/autodoc.py", line 551, in import_object
    __import__(self.modname)
ImportError: No module named gpu.cu
/home/mrule/Dropbox/python_libraries/neurotools/source/neurotools.gpu.cu.convolution.rst:4: WARNING: autodoc: failed to import module u'neurotools.gpu.cu.convolution'; the following exception was raised:
Traceback (most recent call last):
  File "/usr/local/lib/python2.7/dist-packages/sphinx/ext/autodoc.py", line 551, in import_object
    __import__(self.modname)
ImportError: No module named gpu.cu.convolution
/home/mrule/Dropbox/python_libraries/neurotools/source/neurotools.gpu.cu.device.rst:4: WARNING: autodoc: failed to import module u'neurotools.gpu.cu.device'; the following exception was raised:
Traceback (most recent call last):
  File "/usr/local/lib/python2.7/dist-packages/sphinx/ext/autodoc.py", line 551, in import_object
    __import__(self.modname)
ImportError: No module named gpu.cu.device
/home/mrule/Dropbox/python_libraries/neurotools/source/neurotools.gpu.cu.function.rst:4: WARNING: autodoc: failed to import module u'neurotools.gpu.cu.function'; the following exception was raised:
Traceback (most recent call last):
  File "/usr/local/lib/python2.7/dist-packages/sphinx/ext/autodoc.py", line 551, in import_object
    __import__(self.modname)
ImportError: No module named gpu.cu.function
/home/mrule/Dropbox/python_libraries/neurotools/source/neurotools.gpu.cu.gpufun.rst:4: WARNING: autodoc: failed to import module u'neurotools.gpu.cu.gpufun'; the following exception was raised:
Traceback (most recent call last):
  File "/usr/local/lib/python2.7/dist-packages/sphinx/ext/autodoc.py", line 551, in import_object
    __import__(self.modname)
ImportError: No module named gpu.cu.gpufun
/home/mrule/Dropbox/python_libraries/neurotools/source/neurotools.gpu.cu.graph.rst:4: WARNING: autodoc: failed to import module u'neurotools.gpu.cu.graph'; the following exception was raised:
Traceback (most recent call last):
  File "/usr/local/lib/python2.7/dist-packages/sphinx/ext/autodoc.py", line 551, in import_object
    __import__(self.modname)
ImportError: No module named gpu.cu.graph
/home/mrule/Dropbox/python_libraries/neurotools/source/neurotools.gpu.cu.logic.rst:4: WARNING: autodoc: failed to import module u'neurotools.gpu.cu.logic'; the following exception was raised:
Traceback (most recent call last):
  File "/usr/local/lib/python2.7/dist-packages/sphinx/ext/autodoc.py", line 551, in import_object
    __import__(self.modname)
ImportError: No module named gpu.cu.logic
/home/mrule/Dropbox/python_libraries/neurotools/source/neurotools.gpu.cu.matrix.rst:4: WARNING: autodoc: failed to import module u'neurotools.gpu.cu.matrix'; the following exception was raised:
Traceback (most recent call last):
  File "/usr/local/lib/python2.7/dist-packages/sphinx/ext/autodoc.py", line 551, in import_object
    __import__(self.modname)
ImportError: No module named gpu.cu.matrix
/home/mrule/Dropbox/python_libraries/neurotools/source/neurotools.gpu.cu.plot.rst:4: WARNING: autodoc: failed to import module u'neurotools.gpu.cu.plot'; the following exception was raised:
Traceback (most recent call last):
  File "/usr/local/lib/python2.7/dist-packages/sphinx/ext/autodoc.py", line 551, in import_object
    __import__(self.modname)
ImportError: No module named gpu.cu.plot
/home/mrule/Dropbox/python_libraries/neurotools/source/neurotools.gpu.cu.sequence.rst:4: WARNING: autodoc: failed to import module u'neurotools.gpu.cu.sequence'; the following exception was raised:
Traceback (most recent call last):
  File "/usr/local/lib/python2.7/dist-packages/sphinx/ext/autodoc.py", line 551, in import_object
    __import__(self.modname)
ImportError: No module named gpu.cu.sequence
/home/mrule/Dropbox/python_libraries/neurotools/source/neurotools.gpu.cu.statistics.rst:4: WARNING: autodoc: failed to import module u'neurotools.gpu.cu.statistics'; the following exception was raised:
Traceback (most recent call last):
  File "/usr/local/lib/python2.7/dist-packages/sphinx/ext/autodoc.py", line 551, in import_object
    __import__(self.modname)
ImportError: No module named gpu.cu.statistics
/home/mrule/Dropbox/python_libraries/neurotools/source/neurotools.history_basis.rst:4: WARNING: autodoc: failed to import module u'neurotools.history_basis'; the following exception was raised:
Traceback (most recent call last):
  File "/usr/local/lib/python2.7/dist-packages/sphinx/ext/autodoc.py", line 551, in import_object
    __import__(self.modname)
ImportError: No module named history_basis
/home/mrule/Dropbox/python_libraries/neurotools/source/neurotools.hue.rst:4: WARNING: autodoc: failed to import module u'neurotools.hue'; the following exception was raised:
Traceback (most recent call last):
  File "/usr/local/lib/python2.7/dist-packages/sphinx/ext/autodoc.py", line 551, in import_object
    __import__(self.modname)
ImportError: No module named hue
/home/mrule/Dropbox/python_libraries/neurotools/source/neurotools.huetools.rst:4: WARNING: autodoc: failed to import module u'neurotools.huetools'; the following exception was raised:
Traceback (most recent call last):
  File "/usr/local/lib/python2.7/dist-packages/sphinx/ext/autodoc.py", line 551, in import_object
    __import__(self.modname)
ImportError: No module named huetools
/home/mrule/Dropbox/python_libraries/neurotools/source/neurotools.image.rst:4: WARNING: autodoc: failed to import module u'neurotools.image'; the following exception was raised:
Traceback (most recent call last):
  File "/usr/local/lib/python2.7/dist-packages/sphinx/ext/autodoc.py", line 551, in import_object
    __import__(self.modname)
ImportError: No module named image
/home/mrule/Dropbox/python_libraries/neurotools/source/neurotools.jobs.race.rst:4: WARNING: autodoc: failed to import module u'neurotools.jobs.race'; the following exception was raised:
Traceback (most recent call last):
  File "/usr/local/lib/python2.7/dist-packages/sphinx/ext/autodoc.py", line 551, in import_object
    __import__(self.modname)
ImportError: No module named race
/home/mrule/Dropbox/python_libraries/neurotools/source/neurotools.jobs.thunk.rst:4: WARNING: autodoc: failed to import module u'neurotools.jobs.thunk'; the following exception was raised:
Traceback (most recent call last):
  File "/usr/local/lib/python2.7/dist-packages/sphinx/ext/autodoc.py", line 551, in import_object
    __import__(self.modname)
ImportError: No module named thunk
/home/mrule/Dropbox/python_libraries/neurotools/source/neurotools.kent_reimann.rst:4: WARNING: autodoc: failed to import module u'neurotools.kent_reimann'; the following exception was raised:
Traceback (most recent call last):
  File "/usr/local/lib/python2.7/dist-packages/sphinx/ext/autodoc.py", line 551, in import_object
    __import__(self.modname)
ImportError: No module named kent_reimann
/home/mrule/Dropbox/python_libraries/neurotools/source/neurotools.liftools.rst:4: WARNING: autodoc: failed to import module u'neurotools.liftools'; the following exception was raised:
Traceback (most recent call last):
  File "/usr/local/lib/python2.7/dist-packages/sphinx/ext/autodoc.py", line 551, in import_object
    __import__(self.modname)
ImportError: No module named liftools
/home/mrule/Dropbox/python_libraries/neurotools/source/neurotools.linenoise.rst:4: WARNING: autodoc: failed to import module u'neurotools.linenoise'; the following exception was raised:
Traceback (most recent call last):
  File "/usr/local/lib/python2.7/dist-packages/sphinx/ext/autodoc.py", line 551, in import_object
    __import__(self.modname)
ImportError: No module named linenoise
/home/mrule/Dropbox/python_libraries/neurotools/source/neurotools.linenoisetools.rst:4: WARNING: autodoc: failed to import module u'neurotools.linenoisetools'; the following exception was raised:
Traceback (most recent call last):
  File "/usr/local/lib/python2.7/dist-packages/sphinx/ext/autodoc.py", line 551, in import_object
    __import__(self.modname)
ImportError: No module named linenoisetools
/home/mrule/Dropbox/python_libraries/neurotools/source/neurotools.magickernel.rst:4: WARNING: autodoc: failed to import module u'neurotools.magickernel'; the following exception was raised:
Traceback (most recent call last):
  File "/usr/local/lib/python2.7/dist-packages/sphinx/ext/autodoc.py", line 551, in import_object
    __import__(self.modname)
ImportError: No module named magickernel
/home/mrule/Dropbox/python_libraries/neurotools/source/neurotools.modefind.rst:4: WARNING: autodoc: failed to import module u'neurotools.modefind'; the following exception was raised:
Traceback (most recent call last):
  File "/usr/local/lib/python2.7/dist-packages/sphinx/ext/autodoc.py", line 551, in import_object
    __import__(self.modname)
ImportError: No module named modefind
/home/mrule/Dropbox/python_libraries/neurotools/source/neurotools.models.wilson_cowan.compile_to_python.rst:4: WARNING: autodoc: failed to import module u'neurotools.models.wilson_cowan.compile_to_python'; the following exception was raised:
Traceback (most recent call last):
  File "/usr/local/lib/python2.7/dist-packages/sphinx/ext/autodoc.py", line 551, in import_object
    __import__(self.modname)
ImportError: No module named compile_to_python
/home/mrule/Dropbox/python_libraries/neurotools/source/neurotools.models.wilson_cowan.neuralfield.rst:4: WARNING: autodoc: failed to import module u'neurotools.models.wilson_cowan.neuralfield'; the following exception was raised:
Traceback (most recent call last):
  File "/usr/local/lib/python2.7/dist-packages/sphinx/ext/autodoc.py", line 551, in import_object
    __import__(self.modname)
ImportError: No module named neuralfield
/home/mrule/Dropbox/python_libraries/neurotools/source/neurotools.models.wilson_cowan.runmodel.rst:4: WARNING: autodoc: failed to import module u'neurotools.models.wilson_cowan.runmodel'; the following exception was raised:
Traceback (most recent call last):
  File "/usr/local/lib/python2.7/dist-packages/sphinx/ext/autodoc.py", line 551, in import_object
    __import__(self.modname)
ImportError: No module named runmodel
/home/mrule/Dropbox/python_libraries/neurotools/source/neurotools.morlet.rst:4: WARNING: autodoc: failed to import module u'neurotools.morlet'; the following exception was raised:
Traceback (most recent call last):
  File "/usr/local/lib/python2.7/dist-packages/sphinx/ext/autodoc.py", line 551, in import_object
    __import__(self.modname)
ImportError: No module named morlet
/home/mrule/Dropbox/python_libraries/neurotools/source/neurotools.morlet_coherence.rst:4: WARNING: autodoc: failed to import module u'neurotools.morlet_coherence'; the following exception was raised:
Traceback (most recent call last):
  File "/usr/local/lib/python2.7/dist-packages/sphinx/ext/autodoc.py", line 551, in import_object
    __import__(self.modname)
ImportError: No module named morlet_coherence
/home/mrule/Dropbox/python_libraries/neurotools/source/neurotools.multitaper.rst:4: WARNING: autodoc: failed to import module u'neurotools.multitaper'; the following exception was raised:
Traceback (most recent call last):
  File "/usr/local/lib/python2.7/dist-packages/sphinx/ext/autodoc.py", line 551, in import_object
    __import__(self.modname)
ImportError: No module named multitaper
/home/mrule/Dropbox/python_libraries/neurotools/source/neurotools.multitapertools.rst:4: WARNING: autodoc: failed to import module u'neurotools.multitapertools'; the following exception was raised:
Traceback (most recent call last):
  File "/usr/local/lib/python2.7/dist-packages/sphinx/ext/autodoc.py", line 551, in import_object
    __import__(self.modname)
ImportError: No module named multitapertools
/home/mrule/Dropbox/python_libraries/neurotools/source/neurotools.nsignaltools.rst:4: WARNING: autodoc: failed to import module u'neurotools.nsignaltools'; the following exception was raised:
Traceback (most recent call last):
  File "/usr/local/lib/python2.7/dist-packages/sphinx/ext/autodoc.py", line 551, in import_object
    __import__(self.modname)
ImportError: No module named nsignaltools
/home/mrule/Dropbox/python_libraries/neurotools/source/neurotools.opto.rst:4: WARNING: autodoc: failed to import module u'neurotools.opto'; the following exception was raised:
Traceback (most recent call last):
  File "/usr/local/lib/python2.7/dist-packages/sphinx/ext/autodoc.py", line 551, in import_object
    __import__(self.modname)
ImportError: No module named opto
/home/mrule/Dropbox/python_libraries/neurotools/source/neurotools.partools.rst:4: WARNING: autodoc: failed to import module u'neurotools.partools'; the following exception was raised:
Traceback (most recent call last):
  File "/usr/local/lib/python2.7/dist-packages/sphinx/ext/autodoc.py", line 551, in import_object
    __import__(self.modname)
ImportError: No module named partools
/home/mrule/Dropbox/python_libraries/neurotools/source/neurotools.parula.rst:4: WARNING: autodoc: failed to import module u'neurotools.parula'; the following exception was raised:
Traceback (most recent call last):
  File "/usr/local/lib/python2.7/dist-packages/sphinx/ext/autodoc.py", line 551, in import_object
    __import__(self.modname)
ImportError: No module named parula
/home/mrule/Dropbox/python_libraries/neurotools/source/neurotools.phase.rst:4: WARNING: autodoc: failed to import module u'neurotools.phase'; the following exception was raised:
Traceback (most recent call last):
  File "/usr/local/lib/python2.7/dist-packages/sphinx/ext/autodoc.py", line 551, in import_object
    __import__(self.modname)
ImportError: No module named phase
/home/mrule/Dropbox/python_libraries/neurotools/source/neurotools.phasetools.rst:4: WARNING: autodoc: failed to import module u'neurotools.phasetools'; the following exception was raised:
Traceback (most recent call last):
  File "/usr/local/lib/python2.7/dist-packages/sphinx/ext/autodoc.py", line 551, in import_object
    __import__(self.modname)
ImportError: No module named phasetools
/home/mrule/Dropbox/python_libraries/neurotools/source/neurotools.plottools.rst:4: WARNING: autodoc: failed to import module u'neurotools.plottools'; the following exception was raised:
Traceback (most recent call last):
  File "/usr/local/lib/python2.7/dist-packages/sphinx/ext/autodoc.py", line 551, in import_object
    __import__(self.modname)
ImportError: No module named plottools
/home/mrule/Dropbox/python_libraries/neurotools/source/neurotools.ppc.rst:4: WARNING: autodoc: failed to import module u'neurotools.ppc'; the following exception was raised:
Traceback (most recent call last):
  File "/usr/local/lib/python2.7/dist-packages/sphinx/ext/autodoc.py", line 551, in import_object
    __import__(self.modname)
ImportError: No module named ppc
/home/mrule/Dropbox/python_libraries/neurotools/source/neurotools.regressions.rst:4: WARNING: autodoc: failed to import module u'neurotools.regressions'; the following exception was raised:
Traceback (most recent call last):
  File "/usr/local/lib/python2.7/dist-packages/sphinx/ext/autodoc.py", line 551, in import_object
    __import__(self.modname)
ImportError: No module named regressions
/home/mrule/Dropbox/python_libraries/neurotools/source/neurotools.reinterleave.rst:4: WARNING: autodoc: failed to import module u'neurotools.reinterleave'; the following exception was raised:
Traceback (most recent call last):
  File "/usr/local/lib/python2.7/dist-packages/sphinx/ext/autodoc.py", line 551, in import_object
    __import__(self.modname)
ImportError: No module named reinterleave
/home/mrule/Dropbox/python_libraries/neurotools/source/neurotools.resonator.rst:4: WARNING: autodoc: failed to import module u'neurotools.resonator'; the following exception was raised:
Traceback (most recent call last):
  File "/usr/local/lib/python2.7/dist-packages/sphinx/ext/autodoc.py", line 551, in import_object
    __import__(self.modname)
ImportError: No module named resonator
/home/mrule/Dropbox/python_libraries/neurotools/source/neurotools.savitskygolay.rst:4: WARNING: autodoc: failed to import module u'neurotools.savitskygolay'; the following exception was raised:
Traceback (most recent call last):
  File "/usr/local/lib/python2.7/dist-packages/sphinx/ext/autodoc.py", line 551, in import_object
    __import__(self.modname)
ImportError: No module named savitskygolay
/home/mrule/Dropbox/python_libraries/neurotools/source/neurotools.signal.resonator.rst:4: WARNING: autodoc: failed to import module u'neurotools.signal.resonator'; the following exception was raised:
Traceback (most recent call last):
  File "/usr/local/lib/python2.7/dist-packages/sphinx/ext/autodoc.py", line 551, in import_object
    __import__(self.modname)
ImportError: No module named resonator
/home/mrule/Dropbox/python_libraries/neurotools/source/neurotools.spatial.wave_parametric_models.rst:4: WARNING: autodoc: failed to import module u'neurotools.spatial.wave_parametric_models'; the following exception was raised:
Traceback (most recent call last):
  File "/usr/local/lib/python2.7/dist-packages/sphinx/ext/autodoc.py", line 551, in import_object
    __import__(self.modname)
ImportError: No module named wave_parametric_models
/home/mrule/Dropbox/python_libraries/neurotools/source/neurotools.spatialPSD.rst:4: WARNING: autodoc: failed to import module u'neurotools.spatialPSD'; the following exception was raised:
Traceback (most recent call last):
  File "/usr/local/lib/python2.7/dist-packages/sphinx/ext/autodoc.py", line 551, in import_object
    __import__(self.modname)
ImportError: No module named spatialPSD
/home/mrule/Dropbox/python_libraries/neurotools/source/neurotools.spiketools.rst:4: WARNING: autodoc: failed to import module u'neurotools.spiketools'; the following exception was raised:
Traceback (most recent call last):
  File "/usr/local/lib/python2.7/dist-packages/sphinx/ext/autodoc.py", line 551, in import_object
    __import__(self.modname)
ImportError: No module named spiketools
/home/mrule/Dropbox/python_libraries/neurotools/source/neurotools.stats.convolutional.rst:4: WARNING: autodoc: failed to import module u'neurotools.stats.convolutional'; the following exception was raised:
Traceback (most recent call last):
  File "/usr/local/lib/python2.7/dist-packages/sphinx/ext/autodoc.py", line 551, in import_object
    __import__(self.modname)
ImportError: No module named convolutional
/home/mrule/Dropbox/python_libraries/neurotools/source/neurotools.stats.convolutionalmodels.rst:4: WARNING: autodoc: failed to import module u'neurotools.stats.convolutionalmodels'; the following exception was raised:
Traceback (most recent call last):
  File "/usr/local/lib/python2.7/dist-packages/sphinx/ext/autodoc.py", line 551, in import_object
    __import__(self.modname)
ImportError: No module named convolutionalmodels
/home/mrule/Dropbox/python_libraries/neurotools/source/neurotools.stats.fast_kde.rst:4: WARNING: autodoc: failed to import module u'neurotools.stats.fast_kde'; the following exception was raised:
Traceback (most recent call last):
  File "/usr/local/lib/python2.7/dist-packages/sphinx/ext/autodoc.py", line 551, in import_object
    __import__(self.modname)
ImportError: No module named fast_kde
/home/mrule/Dropbox/python_libraries/neurotools/source/neurotools.stats.lessons.rst:4: WARNING: autodoc: failed to import module u'neurotools.stats.lessons'; the following exception was raised:
Traceback (most recent call last):
  File "/usr/local/lib/python2.7/dist-packages/sphinx/ext/autodoc.py", line 551, in import_object
    __import__(self.modname)
ImportError: No module named lessons
/home/mrule/Dropbox/python_libraries/neurotools/source/neurotools.stats.mcint.rst:4: WARNING: autodoc: failed to import module u'neurotools.stats.mcint'; the following exception was raised:
Traceback (most recent call last):
  File "/usr/local/lib/python2.7/dist-packages/sphinx/ext/autodoc.py", line 551, in import_object
    __import__(self.modname)
ImportError: No module named mcint
/home/mrule/Dropbox/python_libraries/neurotools/source/neurotools.stats.mvg.rst:4: WARNING: autodoc: failed to import module u'neurotools.stats.mvg'; the following exception was raised:
Traceback (most recent call last):
  File "/usr/local/lib/python2.7/dist-packages/sphinx/ext/autodoc.py", line 551, in import_object
    __import__(self.modname)
ImportError: No module named mvg
/home/mrule/Dropbox/python_libraries/neurotools/source/neurotools.stats.pvalues.rst:4: WARNING: autodoc: failed to import module u'neurotools.stats.pvalues'; the following exception was raised:
Traceback (most recent call last):
  File "/usr/local/lib/python2.7/dist-packages/sphinx/ext/autodoc.py", line 551, in import_object
    __import__(self.modname)
ImportError: No module named pvalues
/home/mrule/Dropbox/python_libraries/neurotools/source/neurotools.stats.sde.rst:4: WARNING: autodoc: failed to import module u'neurotools.stats.sde'; the following exception was raised:
Traceback (most recent call last):
  File "/usr/local/lib/python2.7/dist-packages/sphinx/ext/autodoc.py", line 551, in import_object
    __import__(self.modname)
ImportError: No module named sde
/home/mrule/Dropbox/python_libraries/neurotools/source/neurotools.stats.spatiotemporal_glm_utils.rst:4: WARNING: autodoc: failed to import module u'neurotools.stats.spatiotemporal_glm_utils'; the following exception was raised:
Traceback (most recent call last):
  File "/usr/local/lib/python2.7/dist-packages/sphinx/ext/autodoc.py", line 551, in import_object
    __import__(self.modname)
ImportError: No module named spatiotemporal_glm_utils
/home/mrule/Dropbox/python_libraries/neurotools/source/neurotools.stattools.rst:4: WARNING: autodoc: failed to import module u'neurotools.stattools'; the following exception was raised:
Traceback (most recent call last):
  File "/usr/local/lib/python2.7/dist-packages/sphinx/ext/autodoc.py", line 551, in import_object
    __import__(self.modname)
ImportError: No module named stattools
/home/mrule/Dropbox/python_libraries/neurotools/source/neurotools.time.rst:4: WARNING: autodoc: failed to import module u'neurotools.time'; the following exception was raised:
Traceback (most recent call last):
  File "/usr/local/lib/python2.7/dist-packages/sphinx/ext/autodoc.py", line 551, in import_object
    __import__(self.modname)
ImportError: No module named time
/home/mrule/Dropbox/python_libraries/neurotools/source/neurotools.timetools.rst:4: WARNING: autodoc: failed to import module u'neurotools.timetools'; the following exception was raised:
Traceback (most recent call last):
  File "/usr/local/lib/python2.7/dist-packages/sphinx/ext/autodoc.py", line 551, in import_object
    __import__(self.modname)
ImportError: No module named timetools
/home/mrule/Dropbox/python_libraries/neurotools/source/neurotools.vonmises.rst:4: WARNING: autodoc: failed to import module u'neurotools.vonmises'; the following exception was raised:
Traceback (most recent call last):
  File "/usr/local/lib/python2.7/dist-packages/sphinx/ext/autodoc.py", line 551, in import_object
    __import__(self.modname)
ImportError: No module named vonmises
/home/mrule/Dropbox/python_libraries/neurotools/source/neurotools.wave_parametric_models.rst:4: WARNING: autodoc: failed to import module u'neurotools.wave_parametric_models'; the following exception was raised:
Traceback (most recent call last):
  File "/usr/local/lib/python2.7/dist-packages/sphinx/ext/autodoc.py", line 551, in import_object
    __import__(self.modname)
ImportError: No module named wave_parametric_models
/home/mrule/Dropbox/python_libraries/neurotools/source/neurotools.waveform.rst:4: WARNING: autodoc: failed to import module u'neurotools.waveform'; the following exception was raised:
Traceback (most recent call last):
  File "/usr/local/lib/python2.7/dist-packages/sphinx/ext/autodoc.py", line 551, in import_object
    __import__(self.modname)
ImportError: No module named waveform
/home/mrule/Dropbox/python_libraries/neurotools/source/modules.rst:: WARNING: document isn't included in any toctree
/home/mrule/Dropbox/python_libraries/neurotools/source/neurotools.20150906_scatter_plots_demonstrating_that_PGD_threshold_creates_confound.rst:: WARNING: document isn't included in any toctree
/home/mrule/Dropbox/python_libraries/neurotools/source/neurotools.20150906_scatter_plots_demonstrating_that_PGD_threshold_creates_confound_2.rst:: WARNING: document isn't included in any toctree
/home/mrule/Dropbox/python_libraries/neurotools/source/neurotools.GLMFit.rst:: WARNING: document isn't included in any toctree
/home/mrule/Dropbox/python_libraries/neurotools/source/neurotools.Statistics.rst:: WARNING: document isn't included in any toctree
/home/mrule/Dropbox/python_libraries/neurotools/source/neurotools.amplitudetransients.rst:: WARNING: document isn't included in any toctree
/home/mrule/Dropbox/python_libraries/neurotools/source/neurotools.array.rst:: WARNING: document isn't included in any toctree
/home/mrule/Dropbox/python_libraries/neurotools/source/neurotools.arraytools.rst:: WARNING: document isn't included in any toctree
/home/mrule/Dropbox/python_libraries/neurotools/source/neurotools.cache.rst:: WARNING: document isn't included in any toctree
/home/mrule/Dropbox/python_libraries/neurotools/source/neurotools.coherence.rst:: WARNING: document isn't included in any toctree
/home/mrule/Dropbox/python_libraries/neurotools/source/neurotools.conv.rst:: WARNING: document isn't included in any toctree
/home/mrule/Dropbox/python_libraries/neurotools/source/neurotools.convolutionalmodels.rst:: WARNING: document isn't included in any toctree
/home/mrule/Dropbox/python_libraries/neurotools/source/neurotools.convtools.rst:: WARNING: document isn't included in any toctree
/home/mrule/Dropbox/python_libraries/neurotools/source/neurotools.dct.rst:: WARNING: document isn't included in any toctree
/home/mrule/Dropbox/python_libraries/neurotools/source/neurotools.decorator.rst:: WARNING: document isn't included in any toctree
/home/mrule/Dropbox/python_libraries/neurotools/source/neurotools.density.rst:: WARNING: document isn't included in any toctree
/home/mrule/Dropbox/python_libraries/neurotools/source/neurotools.densitytools.rst:: WARNING: document isn't included in any toctree
/home/mrule/Dropbox/python_libraries/neurotools/source/neurotools.distance.rst:: WARNING: document isn't included in any toctree
/home/mrule/Dropbox/python_libraries/neurotools/source/neurotools.distancetools.rst:: WARNING: document isn't included in any toctree
/home/mrule/Dropbox/python_libraries/neurotools/source/neurotools.entropy.rst:: WARNING: document isn't included in any toctree
/home/mrule/Dropbox/python_libraries/neurotools/source/neurotools.fftzeros.rst:: WARNING: document isn't included in any toctree
/home/mrule/Dropbox/python_libraries/neurotools/source/neurotools.glm.rst:: WARNING: document isn't included in any toctree
/home/mrule/Dropbox/python_libraries/neurotools/source/neurotools.history_basis.rst:: WARNING: document isn't included in any toctree
/home/mrule/Dropbox/python_libraries/neurotools/source/neurotools.hue.rst:: WARNING: document isn't included in any toctree
/home/mrule/Dropbox/python_libraries/neurotools/source/neurotools.huetools.rst:: WARNING: document isn't included in any toctree
/home/mrule/Dropbox/python_libraries/neurotools/source/neurotools.kent_reimann.rst:: WARNING: document isn't included in any toctree
/home/mrule/Dropbox/python_libraries/neurotools/source/neurotools.lif.rst:: WARNING: document isn't included in any toctree
/home/mrule/Dropbox/python_libraries/neurotools/source/neurotools.liftools.rst:: WARNING: document isn't included in any toctree
/home/mrule/Dropbox/python_libraries/neurotools/source/neurotools.linenoise.rst:: WARNING: document isn't included in any toctree
/home/mrule/Dropbox/python_libraries/neurotools/source/neurotools.linenoisetools.rst:: WARNING: document isn't included in any toctree
/home/mrule/Dropbox/python_libraries/neurotools/source/neurotools.magickernel.rst:: WARNING: document isn't included in any toctree
/home/mrule/Dropbox/python_libraries/neurotools/source/neurotools.matzner_bar-gad_PLoS_2015.rst:: WARNING: document isn't included in any toctree
/home/mrule/Dropbox/python_libraries/neurotools/source/neurotools.modefind.rst:: WARNING: document isn't included in any toctree
/home/mrule/Dropbox/python_libraries/neurotools/source/neurotools.models.wilson_cowan.rst:: WARNING: document isn't included in any toctree
/home/mrule/Dropbox/python_libraries/neurotools/source/neurotools.morlet.rst:: WARNING: document isn't included in any toctree
/home/mrule/Dropbox/python_libraries/neurotools/source/neurotools.morlet_coherence.rst:: WARNING: document isn't included in any toctree
/home/mrule/Dropbox/python_libraries/neurotools/source/neurotools.multitaper.rst:: WARNING: document isn't included in any toctree
/home/mrule/Dropbox/python_libraries/neurotools/source/neurotools.multitapertools.rst:: WARNING: document isn't included in any toctree
/home/mrule/Dropbox/python_libraries/neurotools/source/neurotools.nsignaltools.rst:: WARNING: document isn't included in any toctree
/home/mrule/Dropbox/python_libraries/neurotools/source/neurotools.parallel.rst:: WARNING: document isn't included in any toctree
/home/mrule/Dropbox/python_libraries/neurotools/source/neurotools.partools.rst:: WARNING: document isn't included in any toctree
/home/mrule/Dropbox/python_libraries/neurotools/source/neurotools.parula.rst:: WARNING: document isn't included in any toctree
/home/mrule/Dropbox/python_libraries/neurotools/source/neurotools.phase.rst:: WARNING: document isn't included in any toctree
/home/mrule/Dropbox/python_libraries/neurotools/source/neurotools.phasetools.rst:: WARNING: document isn't included in any toctree
/home/mrule/Dropbox/python_libraries/neurotools/source/neurotools.plottools.rst:: WARNING: document isn't included in any toctree
/home/mrule/Dropbox/python_libraries/neurotools/source/neurotools.ppc.rst:: WARNING: document isn't included in any toctree
/home/mrule/Dropbox/python_libraries/neurotools/source/neurotools.pvalues.rst:: WARNING: document isn't included in any toctree
/home/mrule/Dropbox/python_libraries/neurotools/source/neurotools.regressions.rst:: WARNING: document isn't included in any toctree
/home/mrule/Dropbox/python_libraries/neurotools/source/neurotools.reinterleave.rst:: WARNING: document isn't included in any toctree
/home/mrule/Dropbox/python_libraries/neurotools/source/neurotools.resonator.rst:: WARNING: document isn't included in any toctree
/home/mrule/Dropbox/python_libraries/neurotools/source/neurotools.savitskygolay.rst:: WARNING: document isn't included in any toctree
/home/mrule/Dropbox/python_libraries/neurotools/source/neurotools.signal.dct.rst:: WARNING: document isn't included in any toctree
/home/mrule/Dropbox/python_libraries/neurotools/source/neurotools.spatialPSD.rst:: WARNING: document isn't included in any toctree
/home/mrule/Dropbox/python_libraries/neurotools/source/neurotools.spike.rst:: WARNING: document isn't included in any toctree
/home/mrule/Dropbox/python_libraries/neurotools/source/neurotools.spiketools.rst:: WARNING: document isn't included in any toctree
/home/mrule/Dropbox/python_libraries/neurotools/source/neurotools.stats.convolutionalmodels.rst:: WARNING: document isn't included in any toctree
/home/mrule/Dropbox/python_libraries/neurotools/source/neurotools.stats.magickernel.rst:: WARNING: document isn't included in any toctree
/home/mrule/Dropbox/python_libraries/neurotools/source/neurotools.stats.vonmises.rst:: WARNING: document isn't included in any toctree
/home/mrule/Dropbox/python_libraries/neurotools/source/neurotools.stattools.rst:: WARNING: document isn't included in any toctree
/home/mrule/Dropbox/python_libraries/neurotools/source/neurotools.time.rst:: WARNING: document isn't included in any toctree
/home/mrule/Dropbox/python_libraries/neurotools/source/neurotools.timetools.rst:: WARNING: document isn't included in any toctree
/home/mrule/Dropbox/python_libraries/neurotools/source/neurotools.vonmises.rst:: WARNING: document isn't included in any toctree
/home/mrule/Dropbox/python_libraries/neurotools/source/neurotools.wave_parametric_models.rst:: WARNING: document isn't included in any toctree
